2024-04-14 02:42:27,937 INFO: [31m[1mWARNING: This is a development server. Do not use it in a production deployment. Use a production WSGI server instead.[0m
 * Running on https://localhost:5555 [in /Users/dangnh/Documents/Udacity-az-assignment1/udacity-az1-flask/lib/python3.10/site-packages/werkzeug/_internal.py:96]
2024-04-14 02:42:27,937 INFO: [33mPress CTRL+C to quit[0m [in /Users/dangnh/Documents/Udacity-az-assignment1/udacity-az1-flask/lib/python3.10/site-packages/werkzeug/_internal.py:96]
2024-04-14 02:43:01,016 INFO: 127.0.0.1 - - [14/Apr/2024 02:43:01] "[32mGET / HTTP/1.1[0m" 302 - [in /Users/dangnh/Documents/Udacity-az-assignment1/udacity-az1-flask/lib/python3.10/site-packages/werkzeug/_internal.py:96]
2024-04-14 02:43:01,034 DEBUG: Starting new HTTPS connection (1): login.microsoftonline.com:443 [in /Users/dangnh/Documents/Udacity-az-assignment1/udacity-az1-flask/lib/python3.10/site-packages/urllib3/connectionpool.py:1055]
2024-04-14 02:43:03,776 DEBUG: https://login.microsoftonline.com:443 "GET /dc3d2675-7157-4388-86b5-301e22e0db53/v2.0/.well-known/openid-configuration HTTP/1.1" 200 1753 [in /Users/dangnh/Documents/Udacity-az-assignment1/udacity-az1-flask/lib/python3.10/site-packages/urllib3/connectionpool.py:549]
2024-04-14 02:43:03,780 DEBUG: openid_config = {'token_endpoint': 'https://login.microsoftonline.com/dc3d2675-7157-4388-86b5-301e22e0db53/oauth2/v2.0/token', 'token_endpoint_auth_methods_supported': ['client_secret_post', 'private_key_jwt', 'client_secret_basic'], 'jwks_uri': 'https://login.microsoftonline.com/dc3d2675-7157-4388-86b5-301e22e0db53/discovery/v2.0/keys', 'response_modes_supported': ['query', 'fragment', 'form_post'], 'subject_types_supported': ['pairwise'], 'id_token_signing_alg_values_supported': ['RS256'], 'response_types_supported': ['code', 'id_token', 'code id_token', 'id_token token'], 'scopes_supported': ['openid', 'profile', 'email', 'offline_access'], 'issuer': 'https://login.microsoftonline.com/dc3d2675-7157-4388-86b5-301e22e0db53/v2.0', 'request_uri_parameter_supported': False, 'userinfo_endpoint': 'https://graph.microsoft.com/oidc/userinfo', 'authorization_endpoint': 'https://login.microsoftonline.com/dc3d2675-7157-4388-86b5-301e22e0db53/oauth2/v2.0/authorize', 'device_authorization_endpoint': 'https://login.microsoftonline.com/dc3d2675-7157-4388-86b5-301e22e0db53/oauth2/v2.0/devicecode', 'http_logout_supported': True, 'frontchannel_logout_supported': True, 'end_session_endpoint': 'https://login.microsoftonline.com/dc3d2675-7157-4388-86b5-301e22e0db53/oauth2/v2.0/logout', 'claims_supported': ['sub', 'iss', 'cloud_instance_name', 'cloud_instance_host_name', 'cloud_graph_host_name', 'msgraph_host', 'aud', 'exp', 'iat', 'auth_time', 'acr', 'nonce', 'preferred_username', 'name', 'tid', 'ver', 'at_hash', 'c_hash', 'email'], 'kerberos_endpoint': 'https://login.microsoftonline.com/dc3d2675-7157-4388-86b5-301e22e0db53/kerberos', 'tenant_region_scope': 'AS', 'cloud_instance_name': 'microsoftonline.com', 'cloud_graph_host_name': 'graph.windows.net', 'msgraph_host': 'graph.microsoft.com', 'rbac_url': 'https://pas.windows.net'} [in /Users/dangnh/Documents/Udacity-az-assignment1/udacity-az1-flask/lib/python3.10/site-packages/msal/authority.py:92]
2024-04-14 02:43:03,805 INFO: 127.0.0.1 - - [14/Apr/2024 02:43:03] "GET /login?next=/ HTTP/1.1" 200 - [in /Users/dangnh/Documents/Udacity-az-assignment1/udacity-az1-flask/lib/python3.10/site-packages/werkzeug/_internal.py:96]
2024-04-14 02:43:03,845 INFO: 127.0.0.1 - - [14/Apr/2024 02:43:03] "GET /static/content/bootstrap.min.css HTTP/1.1" 200 - [in /Users/dangnh/Documents/Udacity-az-assignment1/udacity-az1-flask/lib/python3.10/site-packages/werkzeug/_internal.py:96]
2024-04-14 02:43:03,845 INFO: 127.0.0.1 - - [14/Apr/2024 02:43:03] "GET /static/content/site.css HTTP/1.1" 200 - [in /Users/dangnh/Documents/Udacity-az-assignment1/udacity-az1-flask/lib/python3.10/site-packages/werkzeug/_internal.py:96]
2024-04-14 02:43:03,846 INFO: 127.0.0.1 - - [14/Apr/2024 02:43:03] "GET /static/scripts/modernizr-2.6.2.js HTTP/1.1" 200 - [in /Users/dangnh/Documents/Udacity-az-assignment1/udacity-az1-flask/lib/python3.10/site-packages/werkzeug/_internal.py:96]
2024-04-14 02:43:03,847 INFO: 127.0.0.1 - - [14/Apr/2024 02:43:03] "GET /static/images/sign-in-with-ms.svg HTTP/1.1" 200 - [in /Users/dangnh/Documents/Udacity-az-assignment1/udacity-az1-flask/lib/python3.10/site-packages/werkzeug/_internal.py:96]
2024-04-14 02:43:03,849 INFO: 127.0.0.1 - - [14/Apr/2024 02:43:03] "GET /static/scripts/jquery-1.10.2.js HTTP/1.1" 200 - [in /Users/dangnh/Documents/Udacity-az-assignment1/udacity-az1-flask/lib/python3.10/site-packages/werkzeug/_internal.py:96]
2024-04-14 02:43:03,853 INFO: 127.0.0.1 - - [14/Apr/2024 02:43:03] "GET /static/scripts/bootstrap.js HTTP/1.1" 200 - [in /Users/dangnh/Documents/Udacity-az-assignment1/udacity-az1-flask/lib/python3.10/site-packages/werkzeug/_internal.py:96]
2024-04-14 02:43:03,876 INFO: 127.0.0.1 - - [14/Apr/2024 02:43:03] "GET /static/scripts/respond.js HTTP/1.1" 200 - [in /Users/dangnh/Documents/Udacity-az-assignment1/udacity-az1-flask/lib/python3.10/site-packages/werkzeug/_internal.py:96]
2024-04-14 02:43:17,164 DEBUG: Starting new HTTPS connection (1): login.microsoftonline.com:443 [in /Users/dangnh/Documents/Udacity-az-assignment1/udacity-az1-flask/lib/python3.10/site-packages/urllib3/connectionpool.py:1055]
2024-04-14 02:43:19,955 DEBUG: https://login.microsoftonline.com:443 "GET /dc3d2675-7157-4388-86b5-301e22e0db53/v2.0/.well-known/openid-configuration HTTP/1.1" 200 1753 [in /Users/dangnh/Documents/Udacity-az-assignment1/udacity-az1-flask/lib/python3.10/site-packages/urllib3/connectionpool.py:549]
2024-04-14 02:43:19,959 DEBUG: openid_config = {'token_endpoint': 'https://login.microsoftonline.com/dc3d2675-7157-4388-86b5-301e22e0db53/oauth2/v2.0/token', 'token_endpoint_auth_methods_supported': ['client_secret_post', 'private_key_jwt', 'client_secret_basic'], 'jwks_uri': 'https://login.microsoftonline.com/dc3d2675-7157-4388-86b5-301e22e0db53/discovery/v2.0/keys', 'response_modes_supported': ['query', 'fragment', 'form_post'], 'subject_types_supported': ['pairwise'], 'id_token_signing_alg_values_supported': ['RS256'], 'response_types_supported': ['code', 'id_token', 'code id_token', 'id_token token'], 'scopes_supported': ['openid', 'profile', 'email', 'offline_access'], 'issuer': 'https://login.microsoftonline.com/dc3d2675-7157-4388-86b5-301e22e0db53/v2.0', 'request_uri_parameter_supported': False, 'userinfo_endpoint': 'https://graph.microsoft.com/oidc/userinfo', 'authorization_endpoint': 'https://login.microsoftonline.com/dc3d2675-7157-4388-86b5-301e22e0db53/oauth2/v2.0/authorize', 'device_authorization_endpoint': 'https://login.microsoftonline.com/dc3d2675-7157-4388-86b5-301e22e0db53/oauth2/v2.0/devicecode', 'http_logout_supported': True, 'frontchannel_logout_supported': True, 'end_session_endpoint': 'https://login.microsoftonline.com/dc3d2675-7157-4388-86b5-301e22e0db53/oauth2/v2.0/logout', 'claims_supported': ['sub', 'iss', 'cloud_instance_name', 'cloud_instance_host_name', 'cloud_graph_host_name', 'msgraph_host', 'aud', 'exp', 'iat', 'auth_time', 'acr', 'nonce', 'preferred_username', 'name', 'tid', 'ver', 'at_hash', 'c_hash', 'email'], 'kerberos_endpoint': 'https://login.microsoftonline.com/dc3d2675-7157-4388-86b5-301e22e0db53/kerberos', 'tenant_region_scope': 'AS', 'cloud_instance_name': 'microsoftonline.com', 'cloud_graph_host_name': 'graph.windows.net', 'msgraph_host': 'graph.microsoft.com', 'rbac_url': 'https://pas.windows.net'} [in /Users/dangnh/Documents/Udacity-az-assignment1/udacity-az1-flask/lib/python3.10/site-packages/msal/authority.py:92]
2024-04-14 02:43:20,351 DEBUG: https://login.microsoftonline.com:443 "POST /dc3d2675-7157-4388-86b5-301e22e0db53/oauth2/v2.0/token HTTP/1.1" 200 4572 [in /Users/dangnh/Documents/Udacity-az-assignment1/udacity-az1-flask/lib/python3.10/site-packages/urllib3/connectionpool.py:549]
2024-04-14 02:43:20,355 DEBUG: event={
    "client_id": "c213359c-ad1f-4127-ace2-cf3669bb5de1",
    "data": {
        "client_id": "c213359c-ad1f-4127-ace2-cf3669bb5de1",
        "code": "0.AT8AdSY93FdxiEOGtTAeIuDbU5w1E8IfrSdBrOLPNmm7XeFyALw.AgABBAIAAADnfolhJpSnRYB1SVj-Hgd8AgDs_wUA9P_P3bo6tfk8SsyCuLLO7N-BrV8vcAbykAo4qzdGb3-lKVK5_zx9vgBrn1402RL4aY54YjpWQi-XgnktBrEFWXQIm1OQST-9rRMFAi9bnwaYuWF7jfE38VHl8PjV_P097-PN7qGhMsxDxiyK1vszEb1KIvXhGh4wfUcaLSZwSoKUw8bvc6AwXw_zgwWf7yOPLOQeasoJk61GQPX3lFJtvUsFfVgm-KYBEXxDR_VW4mYKakvRqHcpcAYZNZ2rc9sL7UJ9FU59P-V6Be1m4V1VY2y_JDuyaPPvJMXGRpZxUojIKsvo2hzGf8pN7wtyH5Xk5jkza_tNUEE9WdHDet0EyBNT-ardxeXLv2S2D_08ZGgae_kUn75nXpAc03-QnWybXPKR9h6VXegzvrrLPhKHfPWtHhHapMhuNsITZ-jvbLEfad2_z3AuyZjsJFOHNYIEuEOjYBFG_RLeBcy_NPrKwMjbkws6XDkb4FZZiZFwdLOY4tXka76WEGH0YQyYOAyrA-x3wkzVeH8p4cbnD6iPmQxg_-yar1TLH7Wsf53f_-6OiiTkkipwiotGvy-HMO6HKbHu8RnNZ6Bxggi0FZ0xOF6GNuu14mHfB_vQJcbcgMqPUCqW2LFqGgW5kJ_MHa8QDVDNm2UAsz0N66hbZtsxWWHEmSi_SWd3GoyZZZ_CQTAvjXoaCm6-rYNQ_A3VMJlHsUUAhhdksJlT6yYRFTH54P859_3IC-qHwamed_uE6I8n9zYedMs6OuHsUFCmiJ13JsYjtwDX2_uql9GanO_vUaqa5QNJRHNDPxA8",
        "redirect_uri": "https://localhost:5555/callback",
        "scope": [
            "offline_access",
            "User.Read",
            "openid",
            "profile"
        ]
    },
    "grant_type": "authorization_code",
    "params": null,
    "response": {
        "access_token": "********",
        "client_info": "eyJ1aWQiOiI1ZWNlOTQ1MC1mYzUwLTRkMDQtODM4MC1hOTY3NGRhMDk1NmMiLCJ1dGlkIjoiZGMzZDI2NzUtNzE1Ny00Mzg4LTg2YjUtMzAxZTIyZTBkYjUzIn0",
        "expires_in": 5312,
        "ext_expires_in": 5312,
        "id_token": "eyJ0eXAiOiJKV1QiLCJhbGciOiJSUzI1NiIsImtpZCI6InEtMjNmYWxldlpoaEQzaG05Q1Fia1A1TVF5VSJ9.eyJhdWQiOiJjMjEzMzU5Yy1hZDFmLTQxMjctYWNlMi1jZjM2NjliYjVkZTEiLCJpc3MiOiJodHRwczovL2xvZ2luLm1pY3Jvc29mdG9ubGluZS5jb20vZGMzZDI2NzUtNzE1Ny00Mzg4LTg2YjUtMzAxZTIyZTBkYjUzL3YyLjAiLCJpYXQiOjE3MTMwMzcxMDAsIm5iZiI6MTcxMzAzNzEwMCwiZXhwIjoxNzEzMDQxMDAwLCJuYW1lIjoixJDEg25nIE5ndXnhu4VuIEjhuqNpIiwib2lkIjoiNWVjZTk0NTAtZmM1MC00ZDA0LTgzODAtYTk2NzRkYTA5NTZjIiwicHJlZmVycmVkX3VzZXJuYW1lIjoiZGFuZ19hZG1pbkBkYW5ndWRhY2l0eXByYWN0aWNlLm9ubWljcm9zb2Z0LmNvbSIsInJoIjoiMC5BVDhBZFNZOTNGZHhpRU9HdFRBZUl1RGJVNXcxRThJZnJTZEJyT0xQTm1tN1hlRkFBT0EuIiwic3ViIjoiZmw4a3lLQ29LUWVEN0hmTXlVdlRwV2Z1cWN4RUkxb0ZNN1BVay1wVWw5WSIsInRpZCI6ImRjM2QyNjc1LTcxNTctNDM4OC04NmI1LTMwMWUyMmUwZGI1MyIsInV0aSI6IjVKOE9DSjdwWjBTRnhIZ1h0cDBDQUEiLCJ2ZXIiOiIyLjAifQ.BCvdqFsJTjDGyd-ZUZ3h4tfwgvj52IX6NZ6MCMYWVuRfXOLYzE2vYy8XUgrL1rgI13Jfwu_SGbIS6v2D6UpqcbpWWJ_9rRDs9XZhjP0ohv-tBhiCagvuc98BlGkcNh0XZh7hNQRbSHt9h7OoBk4dWxozV53M0qjsLARn7oJ2-Xl5n5h-QnLEHKSFaGqqjdiMyQe6DtTt0Lhzo4RTgyU59RP4jbHdkzGK_bHjDi8d6iEIO_7woVhAZrcThBaDhOhQTPmT1vekFHdxYXrGSJELhJNAlHbWn-QY84Z3U3xgqHBE-8kHbAsC_l70BWHvTNw9AzahE5FQIm51rJj8WJiYCw",
        "refresh_token": "********",
        "scope": "openid profile User.Read email",
        "token_type": "Bearer"
    },
    "scope": [
        "openid",
        "profile",
        "User.Read",
        "email"
    ],
    "token_endpoint": "https://login.microsoftonline.com/dc3d2675-7157-4388-86b5-301e22e0db53/oauth2/v2.0/token"
} [in /Users/dangnh/Documents/Udacity-az-assignment1/udacity-az1-flask/lib/python3.10/site-packages/msal/token_cache.py:116]
2024-04-14 02:43:35,535 ERROR: Exception on /callback [GET] [in /Users/dangnh/Documents/Udacity-az-assignment1/udacity-az1-flask/lib/python3.10/site-packages/flask/app.py:828]
Traceback (most recent call last):
  File "/Users/dangnh/Documents/Udacity-az-assignment1/udacity-az1-flask/lib/python3.10/site-packages/sqlalchemy/engine/base.py", line 145, in __init__
    self._dbapi_connection = engine.raw_connection()
  File "/Users/dangnh/Documents/Udacity-az-assignment1/udacity-az1-flask/lib/python3.10/site-packages/sqlalchemy/engine/base.py", line 3293, in raw_connection
    return self.pool.connect()
  File "/Users/dangnh/Documents/Udacity-az-assignment1/udacity-az1-flask/lib/python3.10/site-packages/sqlalchemy/pool/base.py", line 452, in connect
    return _ConnectionFairy._checkout(self)
  File "/Users/dangnh/Documents/Udacity-az-assignment1/udacity-az1-flask/lib/python3.10/site-packages/sqlalchemy/pool/base.py", line 1269, in _checkout
    fairy = _ConnectionRecord.checkout(pool)
  File "/Users/dangnh/Documents/Udacity-az-assignment1/udacity-az1-flask/lib/python3.10/site-packages/sqlalchemy/pool/base.py", line 716, in checkout
    rec = pool._do_get()
  File "/Users/dangnh/Documents/Udacity-az-assignment1/udacity-az1-flask/lib/python3.10/site-packages/sqlalchemy/pool/impl.py", line 169, in _do_get
    with util.safe_reraise():
  File "/Users/dangnh/Documents/Udacity-az-assignment1/udacity-az1-flask/lib/python3.10/site-packages/sqlalchemy/util/langhelpers.py", line 146, in __exit__
    raise exc_value.with_traceback(exc_tb)
  File "/Users/dangnh/Documents/Udacity-az-assignment1/udacity-az1-flask/lib/python3.10/site-packages/sqlalchemy/pool/impl.py", line 167, in _do_get
    return self._create_connection()
  File "/Users/dangnh/Documents/Udacity-az-assignment1/udacity-az1-flask/lib/python3.10/site-packages/sqlalchemy/pool/base.py", line 393, in _create_connection
    return _ConnectionRecord(self)
  File "/Users/dangnh/Documents/Udacity-az-assignment1/udacity-az1-flask/lib/python3.10/site-packages/sqlalchemy/pool/base.py", line 678, in __init__
    self.__connect()
  File "/Users/dangnh/Documents/Udacity-az-assignment1/udacity-az1-flask/lib/python3.10/site-packages/sqlalchemy/pool/base.py", line 902, in __connect
    with util.safe_reraise():
  File "/Users/dangnh/Documents/Udacity-az-assignment1/udacity-az1-flask/lib/python3.10/site-packages/sqlalchemy/util/langhelpers.py", line 146, in __exit__
    raise exc_value.with_traceback(exc_tb)
  File "/Users/dangnh/Documents/Udacity-az-assignment1/udacity-az1-flask/lib/python3.10/site-packages/sqlalchemy/pool/base.py", line 898, in __connect
    self.dbapi_connection = connection = pool._invoke_creator(self)
  File "/Users/dangnh/Documents/Udacity-az-assignment1/udacity-az1-flask/lib/python3.10/site-packages/sqlalchemy/engine/create.py", line 645, in connect
    return dialect.connect(*cargs, **cparams)
  File "/Users/dangnh/Documents/Udacity-az-assignment1/udacity-az1-flask/lib/python3.10/site-packages/sqlalchemy/engine/default.py", line 616, in connect
    return self.loaded_dbapi.connect(*cargs, **cparams)
pyodbc.OperationalError: ('HYT00', '[HYT00] [Microsoft][ODBC Driver 17 for SQL Server]Login timeout expired (0) (SQLDriverConnect)')

The above exception was the direct cause of the following exception:

Traceback (most recent call last):
  File "/Users/dangnh/Documents/Udacity-az-assignment1/udacity-az1-flask/lib/python3.10/site-packages/flask/app.py", line 1463, in wsgi_app
    response = self.full_dispatch_request()
  File "/Users/dangnh/Documents/Udacity-az-assignment1/udacity-az1-flask/lib/python3.10/site-packages/flask/app.py", line 872, in full_dispatch_request
    rv = self.handle_user_exception(e)
  File "/Users/dangnh/Documents/Udacity-az-assignment1/udacity-az1-flask/lib/python3.10/site-packages/flask/app.py", line 870, in full_dispatch_request
    rv = self.dispatch_request()
  File "/Users/dangnh/Documents/Udacity-az-assignment1/udacity-az1-flask/lib/python3.10/site-packages/flask/app.py", line 855, in dispatch_request
    return self.ensure_sync(self.view_functions[rule.endpoint])(**view_args)  # type: ignore[no-any-return]
  File "/Users/dangnh/Documents/Udacity-az-assignment1/FlaskWebProject/views.py", line 102, in authorized
    user = User.query.filter_by(username="admin").first()
  File "/Users/dangnh/Documents/Udacity-az-assignment1/udacity-az1-flask/lib/python3.10/site-packages/sqlalchemy/orm/query.py", line 2748, in first
    return self.limit(1)._iter().first()  # type: ignore
  File "/Users/dangnh/Documents/Udacity-az-assignment1/udacity-az1-flask/lib/python3.10/site-packages/sqlalchemy/orm/query.py", line 2847, in _iter
    result: Union[ScalarResult[_T], Result[_T]] = self.session.execute(
  File "/Users/dangnh/Documents/Udacity-az-assignment1/udacity-az1-flask/lib/python3.10/site-packages/sqlalchemy/orm/session.py", line 2308, in execute
    return self._execute_internal(
  File "/Users/dangnh/Documents/Udacity-az-assignment1/udacity-az1-flask/lib/python3.10/site-packages/sqlalchemy/orm/session.py", line 2180, in _execute_internal
    conn = self._connection_for_bind(bind)
  File "/Users/dangnh/Documents/Udacity-az-assignment1/udacity-az1-flask/lib/python3.10/site-packages/sqlalchemy/orm/session.py", line 2047, in _connection_for_bind
    return trans._connection_for_bind(engine, execution_options)
  File "<string>", line 2, in _connection_for_bind
  File "/Users/dangnh/Documents/Udacity-az-assignment1/udacity-az1-flask/lib/python3.10/site-packages/sqlalchemy/orm/state_changes.py", line 139, in _go
    ret_value = fn(self, *arg, **kw)
  File "/Users/dangnh/Documents/Udacity-az-assignment1/udacity-az1-flask/lib/python3.10/site-packages/sqlalchemy/orm/session.py", line 1143, in _connection_for_bind
    conn = bind.connect()
  File "/Users/dangnh/Documents/Udacity-az-assignment1/udacity-az1-flask/lib/python3.10/site-packages/sqlalchemy/engine/base.py", line 3269, in connect
    return self._connection_cls(self)
  File "/Users/dangnh/Documents/Udacity-az-assignment1/udacity-az1-flask/lib/python3.10/site-packages/sqlalchemy/engine/base.py", line 147, in __init__
    Connection._handle_dbapi_exception_noconnection(
  File "/Users/dangnh/Documents/Udacity-az-assignment1/udacity-az1-flask/lib/python3.10/site-packages/sqlalchemy/engine/base.py", line 2431, in _handle_dbapi_exception_noconnection
    raise sqlalchemy_exception.with_traceback(exc_info[2]) from e
  File "/Users/dangnh/Documents/Udacity-az-assignment1/udacity-az1-flask/lib/python3.10/site-packages/sqlalchemy/engine/base.py", line 145, in __init__
    self._dbapi_connection = engine.raw_connection()
  File "/Users/dangnh/Documents/Udacity-az-assignment1/udacity-az1-flask/lib/python3.10/site-packages/sqlalchemy/engine/base.py", line 3293, in raw_connection
    return self.pool.connect()
  File "/Users/dangnh/Documents/Udacity-az-assignment1/udacity-az1-flask/lib/python3.10/site-packages/sqlalchemy/pool/base.py", line 452, in connect
    return _ConnectionFairy._checkout(self)
  File "/Users/dangnh/Documents/Udacity-az-assignment1/udacity-az1-flask/lib/python3.10/site-packages/sqlalchemy/pool/base.py", line 1269, in _checkout
    fairy = _ConnectionRecord.checkout(pool)
  File "/Users/dangnh/Documents/Udacity-az-assignment1/udacity-az1-flask/lib/python3.10/site-packages/sqlalchemy/pool/base.py", line 716, in checkout
    rec = pool._do_get()
  File "/Users/dangnh/Documents/Udacity-az-assignment1/udacity-az1-flask/lib/python3.10/site-packages/sqlalchemy/pool/impl.py", line 169, in _do_get
    with util.safe_reraise():
  File "/Users/dangnh/Documents/Udacity-az-assignment1/udacity-az1-flask/lib/python3.10/site-packages/sqlalchemy/util/langhelpers.py", line 146, in __exit__
    raise exc_value.with_traceback(exc_tb)
  File "/Users/dangnh/Documents/Udacity-az-assignment1/udacity-az1-flask/lib/python3.10/site-packages/sqlalchemy/pool/impl.py", line 167, in _do_get
    return self._create_connection()
  File "/Users/dangnh/Documents/Udacity-az-assignment1/udacity-az1-flask/lib/python3.10/site-packages/sqlalchemy/pool/base.py", line 393, in _create_connection
    return _ConnectionRecord(self)
  File "/Users/dangnh/Documents/Udacity-az-assignment1/udacity-az1-flask/lib/python3.10/site-packages/sqlalchemy/pool/base.py", line 678, in __init__
    self.__connect()
  File "/Users/dangnh/Documents/Udacity-az-assignment1/udacity-az1-flask/lib/python3.10/site-packages/sqlalchemy/pool/base.py", line 902, in __connect
    with util.safe_reraise():
  File "/Users/dangnh/Documents/Udacity-az-assignment1/udacity-az1-flask/lib/python3.10/site-packages/sqlalchemy/util/langhelpers.py", line 146, in __exit__
    raise exc_value.with_traceback(exc_tb)
  File "/Users/dangnh/Documents/Udacity-az-assignment1/udacity-az1-flask/lib/python3.10/site-packages/sqlalchemy/pool/base.py", line 898, in __connect
    self.dbapi_connection = connection = pool._invoke_creator(self)
  File "/Users/dangnh/Documents/Udacity-az-assignment1/udacity-az1-flask/lib/python3.10/site-packages/sqlalchemy/engine/create.py", line 645, in connect
    return dialect.connect(*cargs, **cparams)
  File "/Users/dangnh/Documents/Udacity-az-assignment1/udacity-az1-flask/lib/python3.10/site-packages/sqlalchemy/engine/default.py", line 616, in connect
    return self.loaded_dbapi.connect(*cargs, **cparams)
sqlalchemy.exc.OperationalError: (pyodbc.OperationalError) ('HYT00', '[HYT00] [Microsoft][ODBC Driver 17 for SQL Server]Login timeout expired (0) (SQLDriverConnect)')
(Background on this error at: https://sqlalche.me/e/20/e3q8)
2024-04-14 02:43:35,546 INFO: 127.0.0.1 - - [14/Apr/2024 02:43:35] "[35m[1mGET /callback?code=0.AT8AdSY93FdxiEOGtTAeIuDbU5w1E8IfrSdBrOLPNmm7XeFyALw.AgABBAIAAADnfolhJpSnRYB1SVj-Hgd8AgDs_wUA9P_P3bo6tfk8SsyCuLLO7N-BrV8vcAbykAo4qzdGb3-lKVK5_zx9vgBrn1402RL4aY54YjpWQi-XgnktBrEFWXQIm1OQST-9rRMFAi9bnwaYuWF7jfE38VHl8PjV_P097-PN7qGhMsxDxiyK1vszEb1KIvXhGh4wfUcaLSZwSoKUw8bvc6AwXw_zgwWf7yOPLOQeasoJk61GQPX3lFJtvUsFfVgm-KYBEXxDR_VW4mYKakvRqHcpcAYZNZ2rc9sL7UJ9FU59P-V6Be1m4V1VY2y_JDuyaPPvJMXGRpZxUojIKsvo2hzGf8pN7wtyH5Xk5jkza_tNUEE9WdHDet0EyBNT-ardxeXLv2S2D_08ZGgae_kUn75nXpAc03-QnWybXPKR9h6VXegzvrrLPhKHfPWtHhHapMhuNsITZ-jvbLEfad2_z3AuyZjsJFOHNYIEuEOjYBFG_RLeBcy_NPrKwMjbkws6XDkb4FZZiZFwdLOY4tXka76WEGH0YQyYOAyrA-x3wkzVeH8p4cbnD6iPmQxg_-yar1TLH7Wsf53f_-6OiiTkkipwiotGvy-HMO6HKbHu8RnNZ6Bxggi0FZ0xOF6GNuu14mHfB_vQJcbcgMqPUCqW2LFqGgW5kJ_MHa8QDVDNm2UAsz0N66hbZtsxWWHEmSi_SWd3GoyZZZ_CQTAvjXoaCm6-rYNQ_A3VMJlHsUUAhhdksJlT6yYRFTH54P859_3IC-qHwamed_uE6I8n9zYedMs6OuHsUFCmiJ13JsYjtwDX2_uql9GanO_vUaqa5QNJRHNDPxA8&state=f6e4c10b-721b-4f26-9c5e-66f7d0afe698&session_state=66111766-5422-4890-9977-891d624d5d85 HTTP/1.1[0m" 500 - [in /Users/dangnh/Documents/Udacity-az-assignment1/udacity-az1-flask/lib/python3.10/site-packages/werkzeug/_internal.py:96]
